Workbook
Name Average_BD: 'Rough for 1st chart'!$F$8
Name Average_other: 'Rough for 1st chart'!$F$7
Name percent: 'Rough for 2nd chart'!$F$9

Sheet GDP_1975_2025_uploaded
A1: Country | B1: 1975 | C1: 1976 | D1: 1977 | E1: 1978 | F1: 1979 | G1: 1980 | H1: 1981 | I1: 1982 | J1: 1983 | K1: 1984 | L1: 1985 | M1: 1986 | N1: 1987 | O1: 1988 | P1: 1989 | Q1: 1990 | R1: 1991 | S1: 1992 | T1: 1993 | U1: 1994 | V1: 1995 | W1: 1996 | X1: 1997 | Y1: 1998 | Z1: 1999 | AA1: 2000 | AB1: 2001 | AC1: 2002 | AD1: 2003 | AE1: 2004 | AF1: 2005 | AG1: 2006 | AH1: 2007 | AI1: 2008 | AJ1: 2009 | AK1: 2010 | AL1: 2011 | AM1: 2012 | AN1: 2013 | AO1: 2014 | AP1: 2015 | AQ1: 2016 | AR1: 2017 | AS1: 2018 | AT1: 2019 | AU1: 2020 | AV1: 2021 | AW1: 2022 | AX1: 2023 | AY1: 2024 | AZ1: 2025
A2: Afghanistan | B2: 2367 | C2: 2556 | D2: 2953 | E2: 3300 | F2: 3698 | AC2: 4367 | AD2: 4553 | AE2: 5146 | AF2: 6167 | AG2: 6925 | AH2: 8556 | AI2: 10297 | AJ2: 12066 | AK2: 15325 | AL2: 17890 | AM2: 20293 | AN2: 20170 | AO2: 20616 | AP2: 20057 | AQ2: 18020 | AR2: 18883 | AS2: 18336 | AT2: 18876 | AU2: 20136 | AV2: 14278 | AW2: 14501 | AX2: 17248
A3: Albania | B3: 2610 | C3: 2686 | D3: 2761 | E3: 2842 | F3: 2372 | G3: 1969 | H3: 2256 | I3: 2323 | J3: 2347 | K3: 2317 | L3: 2366 | M3: 2617 | N3: 2597 | O3: 2560 | P3: 2812 | Q3: 2247 | R3: 1349 | S3: 853 | T3: 1478 | U3: 2389 | V3: 2916 | W3: 3238 | X3: 2251 | Y3: 2585 | Z3: 3264 | AA3: 3529 | AB3: 3974 | AC3: 4408 | AD3: 5628 | AE3: 7263 | AF3: 8148 | AG3: 9002 | AH3: 10804 | AI3: 13035 | AJ3: 12187 | AK3: 12079 | AL3: 13052 | AM3: 12470 | AN3: 12936 | AO3: 13404 | AP3: 11525 | AQ3: 12003 | AR3: 13209 | AS3: 15337 | AT3: 15582 | AU3: 15271 | AV3: 18086 | AW3: 19185 | AX3: 23388 | AY3: 27259 | AZ3: 28372
A4: Algeria | B4: 15591 | C4: 17790 | D4: 21038 | E4: 26433 | F4: 33276 | G4: 45957 | H4: 48156 | I4: 48599 | J4: 51582 | K4: 55906 | L4: 66346 | M4: 66783 | N4: 68698 | O4: 56070 | P4: 57041 | Q4: 67171 | R4: 50650 | S4: 53414 | T4: 55309 | U4: 46044 | V4: 45654 | W4: 50945 | X4: 52287 | Y4: 52297 | Z4: 53011 | AA4: 59418 | AB4: 59413 | AC4: 61516 | AD4: 73482 | AE4: 91914 | AF4: 107047 | AG4: 123084 | AH4: 142483 | AI4: 180384 | AJ4: 150317 | AK4: 177785 | AL4: 218332 | AM4: 227144 | AN4: 229701 | AO4: 238943 | AP4: 187494 | AQ4: 180764 | AR4: 190004 | AS4: 194507 | AT4: 193361 | AU4: 164774 | AV4: 185850 | AW4: 225709 | AX4: 247789 | AY4: 264913 | AZ4: 268885
A5: Andorra | B5: 279 | C5: 288 | D5: 321 | E5: 390 | F5: 521 | AA5: 1429 | AB5: 1547 | AC5: 1758 | AD5: 2362 | AE5: 2896 | AF5: 3158 | AG5: 3456 | AH5: 3952 | AI5: 4082 | AJ5: 3675 | AK5: 3446 | AL5: 3625 | AM5: 3189 | AN5: 3193 | AO5: 3267 | AP5: 2789 | AQ5: 2895 | AR5: 2993 | AS5: 3217 | AT5: 3155 | AU5: 2885 | AV5: 3325 | AW5: 3376 | AX5: 3786 | AY5: 4038 | AZ5: 4035
A6: Angola | B6: 4147 | C6: 3981 | D6: 4344 | E6: 4845 | F6: 5380 | G6: 8730 | H6: 8170 | I6: 8170 | J6: 8514 | K6: 9025 | L6: 11119 | M6: 10411 | N6: 11900 | O6: 12909 | P6: 15017 | Q6: 16529 | R6: 16022 | S6: 12354 | T6: 8966 | U6: 6529 | V6: 8148 | W6: 10510 | X6: 12344 | Y6: 10464 | Z6: 9895 | AA6: 12646 | AB6: 12378 | AC6: 17312 | AD6: 20342 | AE6: 26998 | AF6: 41397 | AG6: 58654 | AH6: 73038 | AI6: 98790 | AJ6: 81705 | AK6: 95547 | AL6: 125552 | AM6: 143573 | AN6: 153761 | AO6: 164448 | AP6: 131661 | AQ6: 114764 | AR6: 139835 | AS6: 114189 | AT6: 94671 | AU6: 66521 | AV6: 84375 | AW6: 142442 | AX6: 109764 | AY6: 115946 | AZ6: 113343
A7: Antigua and Barbuda | B7: 85 | C7: 71 | D7: 81 | E7: 92 | F7: 113 | G7: 132 | H7: 149 | I7: 166 | J7: 185 | K7: 212 | L7: 246 | M7: 298 | N7: 347 | O7: 411 | P7: 455 | Q7: 479 | R7: 504 | S7: 525 | T7: 566 | U7: 625 | V7: 616 | W7: 679 | X7: 734 | Y7: 790 | Z7: 836 | AA7: 901 | AB7: 878 | AC7: 898 | AD7: 948 | AE7: 1026 | AF7: 1144 | AG7: 1304 | AH7: 1487 | AI7: 1558 | AJ7: 1387 | AK7: 1298 | AL7: 1287 | AM7: 1365 | AN7: 1325 | AO7: 1379 | AP7: 1437 | AQ7: 1490 | AR7: 1535 | AS7: 1662 | AT7: 1726 | AU7: 1412 | AV7: 1602 | AW7: 1867 | AX7: 2006 | AY7: 2225 | AZ7: 2373
A8: Argentina | B8: 51741 | C8: 54575 | D8: 61662 | E8: 63865 | F8: 73987 | G8: 233696 | H8: 189802 | I8: 94250 | J8: 116267 | K8: 130544 | L8: 98599 | M8: 118565 | N8: 121561 | O8: 142386 | P8: 91352 | Q8: 158024 | R8: 211979 | S8: 255787 | T8: 264429 | U8: 287835 | V8: 288497 | W8: 304282 | X8: 327436 | Y8: 334244 | Z8: 316998 | AA8: 317759 | AB8: 300421 | AC8: 112458 | AD8: 142431 | AE8: 164911 | AF8: 199273 | AG8: 232892 | AH8: 287921 | AI8: 363545 | AJ8: 334633 | AK8: 424729 | AL8: 527644 | AM8: 579666 | AN8: 611471 | AO8: 563614 | AP8: 642464 | AQ8: 556774 | AR8: 643861 | AS8: 524431 | AT8: 446762 | AU8: 385218 | AV8: 486040 | AW8: 632318 | AX8: 645511 | AY8: 632145 | AZ8: 683533
A9: Armenia | S9: 108 | T9: 835 | U9: 648 | V9: 1287 | W9: 1597 | X9: 1639 | Y9: 1892 | Z9: 1845 | AA9: 1912 | AB9: 2118 | AC9: 2376 | AD9: 2807 | AE9: 3577 | AF9: 4900 | AG9: 6384 | AH9: 9206 | AI9: 11662 | AJ9: 8648 | AK9: 9260 | AL9: 10142 | AM9: 10619 | AN9: 11121 | AO9: 11610 | AP9: 10553 | AQ9: 10546 | AR9: 11527 | AS9: 12458 | AT9: 13619 | AU9: 12642 | AV9: 13879 | AW9: 19514 | AX9: 24086 | AY9: 25533 | AZ9: 26258
A10: Aruba | B10: 229 | C10: 241 | D10: 254 | E10: 268 | F10: 282 | V10: 1321 | W10: 1380 | X10: 1532 | Y10: 1665 | Z10: 1723 | AA10: 1873 | AB10: 1896 | AC10: 1962 | AD10: 2044 | AE10: 2255 | AF10: 2360 | AG10: 2470 | AH10: 2678 | AI10: 2843 | AJ10: 2554 | AK10: 2454 | AL10: 2638 | AM10: 2615 | AN10: 2728 | AO10: 2791 | AP10: 2963 | AQ10: 2984 | AR10: 3092 | AS10: 3276 | AT10: 3341 | AU10: 2486 | AV10: 2929 | AW10: 3279 | AX10: 3649 | AY10: 3952 | AZ10: 4100
A11: Australia | B11: 108853 | C11: 117298 | D11: 116222 | E11: 135608 | F11: 150133 | G11: 162924 | H11: 188410 | I11: 187049 | J11: 179478 | K11: 197136 | L11: 174385 | M11: 181477 | N11: 213100 | O11: 271088 | P11: 308402 | Q11: 324128 | R11: 324436 | S11: 318005 | T11: 309303 | U11: 353372 | V11: 379227 | W11: 424663 | X11: 426401 | Y11: 381498 | Z11: 411968 | AA11: 400278 | AB11: 378114 | AC11: 425516 | AD11: 541155 | AE11: 658742 | AF11: 736505 | AG11: 783447 | AH11: 950093 | AI11: 1056559 | AJ11: 1000828 | AK11: 1254623 | AL11: 1515507 | AM11: 1570139 | AN11: 1519900 | AO11: 1456939 | AP11: 1233921 | AQ11: 1262655 | AR11: 1381110 | AS11: 1417162 | AT11: 1386277 | AU11: 1362613 | AV11: 1655843 | AW11: 1725461 | AX11: 1742461 | AY11: 1796805 | AZ11: 1771681
A12: Austria | B12: 39962 | C12: 42856 | D12: 51423 | E12: 61901 | F12: 73763 | G12: 80481 | H12: 69738 | I12: 69727 | J12: 70644 | K12: 66640 | L12: 68248 | M12: 96842 | N12: 121104 | O12: 132860 | P12: 132534 | Q12: 165953 | R12: 173481 | S12: 194436 | T12: 189342 | U12: 202854 | V12: 239914 | W12: 236044 | X12: 211978 | Y12: 217363 | Z12: 216637 | AA12: 196268 | AB12: 196479 | AC12: 212687 | AD12: 260714 | AE12: 299075 | AF12: 314126 | AG12: 333924 | AH12: 386806 | AI12: 429187 | AJ12: 398857 | AK12: 390146 | AL12: 428879 | AM12: 407008 | AN12: 426587 | AO12: 438669 | AP12: 379584 | AQ12: 393579 | AR12: 414780 | AS12: 452787 | AT12: 443033 | AU12: 434050 | AV12: 480786 | AW12: 472339 | AX12: 512509 | AY12: 521269 | AZ12: 534301
A13: Azerbaijan | S13: 1193 | T13: 1309 | U13: 2258 | V13: 2417 | W13: 3177 | X13: 4317 | Y13: 4280 | Z13: 4581 | AA13: 5273 | AB13: 5475 | AC13: 6232 | AD13: 7276 | AE13: 8682 | AF13: 13239 | AG13: 20983 | AH13: 33050 | AI13: 48852 | AJ13: 44297 | AK13: 52909 | AL13: 65952 | AM13: 69684 | AN13: 74164 | AO13: 75235 | AP13: 52997 | AQ13: 37830 | AR13: 41375 | AS13: 47113 | AT13: 48174 | AU13: 42693 | AV13: 54825 | AW13: 78807 | AX13: 72428 | AY13: 74316 | AZ13: 78870
A14: Bahamas | B14: 892 | C14: 971 | D14: 1162 | E14: 1336 | F14: 1579 | G14: 2598 | H14: 2692 | I14: 3031 | J14: 3373 | K14: 3603 | L14: 3923 | M14: 4241 | N14: 4669 | O14: 4855 | P14: 5473 | Q14: 5218 | R14: 5128 | S14: 5125 | T14: 5097 | U14: 5372 | V14: 5653 | W14: 5950 | X14: 6332 | Y14: 6833 | Z14: 7684 | AA14: 8076 | AB14: 8318 | AC14: 8881 | AD14: 8870 | AE14: 9055 | AF14: 9836 | AG14: 10167 | AH14: 10618 | AI14: 10526 | AJ14: 9982 | AK14: 10096 | AL14: 10070 | AM14: 10720 | AN14: 10396 | AO14: 10974 | AP14: 11672 | AQ14: 11745 | AR14: 12237 | AS14: 12616 | AT14: 13016 | AU14: 9958 | AV14: 11369 | AW14: 13136 | AX14: 14338 | AY14: 14761 | AZ14: 15178
A15: Bahrain | B15: 1185 | C15: 1705 | D15: 2144 | E15: 2449 | F15: 2920 | G15: 3745 | H15: 4228 | I15: 4445 | J15: 4554 | K15: 4727 | L15: 4460 | M15: 3490 | N15: 3780 | O15: 4672 | P15: 4873 | Q15: 5176 | R15: 5430 | S15: 5673 | T15: 6241 | U15: 6683 | V15: 7075 | W15: 7357 | X15: 7629 | Y15: 7293 | Z15: 7905 | AA15: 9448 | AB15: 9579 | AC15: 10001 | AD15: 11546 | AE15: 13709 | AF15: 16647 | AG15: 19291 | AH15: 22653 | AI15: 26803 | AJ15: 23913 | AK15: 26806 | AL15: 29915 | AM15: 31963 | AN15: 33823 | AO15: 34773 | AP15: 32523 | AQ15: 33885 | AR15: 37205 | AS15: 39568 | AT15: 40447 | AU15: 35838 | AV15: 40840 | AW15: 46458 | AX15: 46192 | AY15: 46943 | AZ15: 47829
A16: Bangladesh | B16: 8476 | C16: 9447 | D16: 9950 | E16: 12751 | F16: 14758 | G16: 24775 | H16: 26355 | I16: 24678 | J16: 23904 | K16: 26817 | L16: 28819 | M16: 29639 | N16: 32449 | O16: 34914 | P16: 38070 | Q16: 41068 | R16: 42488 | S16: 43292 | T16: 43684 | U16: 46438 | V16: 51842 | W16: 55445 | X16: 57599 | Y16: 59879 | Z16: 61526 | AA16: 61687 | AB16: 62537 | AC16: 65036 | AD16: 71755 | AE16: 77152 | AF16: 79530 | AG16: 86028 | AH16: 95374 | AI16: 109765 | AJ16: 122760 | AK16: 138094 | AL16: 154097 | AM16: 159749 | AN16: 179676 | AO16: 207102 | AP16: 233687 | AQ16: 265236 | AR16: 293755 | AS16: 321379 | AT16: 351238 | AU16: 373902 | AV16: 416265 | AW16: 460201 | AX16: 451534 | AY16: 451096 | AZ16: 467218
A17: Barbados | B17: 476 | C17: 517 | D17: 588 | E17: 658 | F17: 798 | G17: 1048 | H17: 1154 | I17: 1205 | J17: 1280 | K17: 1395 | L17: 1460 | M17: 1603 | N17: 1765 | O17: 1877 | P17: 2077 | Q17: 2084 | R17: 2092 | S17: 2015 | T17: 2136 | U17: 2227 | V17: 2348 | W17: 2515 | X17: 2667 | Y17: 3057 | Z17: 3210 | AA17: 3312 | AB17: 3306 | AC17: 3364 | AD17: 3479 | AE17: 3754 | AF17: 4213 | AG17: 4702 | AH17: 5273 | AI17: 5401 | AJ17: 5064 | AK17: 5138 | AL17: 5302 | AM17: 5233 | AN17: 5338 | AO17: 5366 | AP17: 5288 | AQ17: 5331 | AR17: 5517 | AS17: 5630 | AT17: 5788 | AU17: 5168 | AV17: 5275 | AW17: 6257 | AX17: 6721 | AY17: 7167 | AZ17: 7552
A18: Belarus | S18: 12800 | T18: 11408 | U18: 15687 | V18: 10532 | W18: 14494 | X18: 14091 | Y18: 15215 | Z18: 12133 | AA18: 10785 | AB18: 12778 | AC18: 15092 | AD18: 18420 | AE18: 23928 | AF18: 31239 | AG18: 38219 | AH18: 46815 | AI18: 62798 | AJ18: 50855 | AK18: 57220 | AL18: 61368 | AM18: 65669 | AN18: 75496 | AO18: 78736 | AP18: 56329 | AQ18: 47703 | AR18: 54723 | AS18: 60011 | AT18: 64414 | AU18: 61312 | AV18: 68207 | AW18: 73735 | AX18: 71792 | AY18: 71180 | AZ18: 71561
A19: Belgium | B19: 66028 | C19: 71495 | D19: 83282 | E19: 101793 | F19: 116940 | G19: 123479 | H19: 102245 | I19: 89959 | J19: 85037 | K19: 81237 | L19: 84468 | M19: 117063 | N19: 145412 | O19: 158098 | P19: 159817 | Q19: 200150 | R19: 205370 | S19: 228733 | T19: 218721 | U19: 238623 | V19: 288302 | W19: 279292 | X19: 253022 | Y19: 258876 | Z19: 258503 | AA19: 236897 | AB19: 236748 | AC19: 258200 | AD19: 318004 | AE19: 369047 | AF19: 385927 | AG19: 408281 | AH19: 470978 | AI19: 517271 | AJ19: 484488 | AK19: 481949 | AL19: 527106 | AM19: 498731 | AN19: 524106 | AO19: 538127 | AP19: 461091 | AQ19: 474141 | AR19: 500733 | AS19: 542885 | AT19: 536787 | AU19: 529269 | AV19: 598892 | AW19: 593906 | AX19: 644968 | AY19: 664965 | AZ19: 684864
A20: Belize | B20: 104 | C20: 82 | D20: 106 | E20: 121 | F20: 141 | G20: 229 | H20: 238 | I20: 238 | J20: 251 | K20: 280 | L20: 278 | M20: 303 | N20: 354 | O20: 418 | P20: 482 | Q20: 547 | R20: 597 | S20: 696 | T20: 753 | U20: 772 | V20: 819 | W20: 851 | X20: 873 | Y20: 929 | Z20: 1000 | AA20: 1139 | AB20: 1173 | AC20: 1245 | AD20: 1309 | AE20: 1401 | AF20: 1475 | AG20: 1591 | AH20: 1707 | AI20: 1739 | AJ20: 1688 | AK20: 1746 | AL20: 1827 | AM20: 1909 | AN20: 2033 | AO20: 2138 | AP20: 2193 | AQ20: 2240 | AR20: 2266 | AS20: 2293 | AT20: 2388 | AU20: 2043 | AV20: 2421 | AW20: 2847 | AX20: 3067 | AY20: 3427 | AZ20: 3611
A21: Benin | B21: 674 | C21: 718 | D21: 786 | E21: 954 | F21: 1162 | G21: 2302 | H21: 1557 | I21: 1542 | J21: 1365 | K21: 1456 | L21: 1580 | M21: 2036 | N21: 2430 | O21: 2552 | P21: 2370 | Q21: 2890 | R21: 2954 | S21: 3284 | T21: 3199 | U21: 2227 | V21: 2993 | W21: 3251 | X21: 3124 | Y21: 3362 | Z21: 3681 | AA21: 3522 | AB21: 3666 | AC21: 4191 | AD21: 5348 | AE21: 6187 | AF21: 6571 | AG21: 7034 | AH21: 8170 | AI21: 9787 | AJ21: 9728 | AK21: 9543 | AL21: 10691 | AM21: 11148 | AN21: 12518 | AO21: 13288 | AP21: 11389 | AQ21: 11818 | AR21: 12697 | AS21: 14257 | AT21: 14392 | AU21: 15674 | AV21: 17699 | AW21: 17439 | AX21: 19679 | AY21: 21249 | AZ21: 22236
A22: Bhutan | B22: 87 | C22: 88 | D22: 98 | E22: 94 | F22: 105 | G22: 132 | H22: 143 | I22: 150 | J22: 162 | K22: 168 | L22: 174 | M22: 197 | N22: 238 | O22: 273 | P22: 272 | Q22: 293 | R22: 254 | S22: 248 | T22: 260 | U22: 263 | V22: 308 | W22: 324 | X22: 362 | Y22: 398 | Z22: 418 | AA22: 454 | AB22: 474 | AC22: 517 | AD22: 616 | AE22: 700 | AF22: 818 | AG22: 876 | AH22: 1071 | AI22: 1353 | AJ22: 1274 | AK22: 1528 | AL22: 1880 | AM22: 1967 | AN22: 1999 | AO22: 1963 | AP22: 2159 | AQ22: 2252 | AR22: 2462 | AS22: 2651 | AT22: 2618 | AU22: 2586 | AV22: 2623 | AW22: 2869 | AX22: 2923 | AY22: 3092 | AZ22: 3422
A23: Bolivia | B23: 2399 | C23: 2749 | D23: 2765 | E23: 3020 | F23: 3274 | G23: 3589 | H23: 3440 | I23: 3813 | J23: 3609 | K23: 3752 | L23: 4059 | M23: 3970 | N23: 4323 | O23: 4598 | P23: 4716 | Q23: 4868 | R23: 5335 | S23: 5635 | T23: 5724 | U23: 5974 | V23: 6707 | W23: 7385 | X23: 7919 | Y23: 8490 | Z23: 8269 | AA23: 8385 | AB23: 8155 | AC23: 7917 | AD23: 8092 | AE23: 8785 | AF23: 9573 | AG23: 11520 | AH23: 13216 | AI23: 16792 | AJ23: 17464 | AK23: 19786 | AL23: 24135 | AM23: 27282 | AN23: 30883 | AO23: 33237 | AP23: 33241 | AQ23: 34189 | AR23: 37782 | AS23: 40581 | AT23: 41193 | AU23: 36897 | AV23: 40701 | AW23: 44329 | AX23: 45464 | AY23: 48404 | AZ23: 56339
A24: Bosnia and Herzegovina | W24: 3584 | X24: 4578 | Y24: 5281 | Z24: 5766 | AA24: 5568 | AB24: 5801 | AC24: 6728 | AD24: 8499 | AE24: 10157 | AF24: 11223 | AG24: 12865 | AH24: 15779 | AI24: 19113 | AJ24: 17614 | AK24: 17176 | AL24: 18644 | AM24: 17227 | AN24: 18179 | AO24: 18559 | AP24: 16404 | AQ24: 17117 | AR24: 18326 | AS24: 20484 | AT24: 20483 | AU24: 20226 | AV24: 23673 | AW24: 24535 | AX24: 27592 | AY24: 28795 | AZ24: 28807
A25: Botswana | B25: 274 | C25: 297 | D25: 383 | E25: 456 | F25: 595 | G25: 1174 | H25: 1037 | I25: 1094 | J25: 1208 | K25: 1200 | L25: 1117 | M25: 1515 | N25: 2374 | O25: 3082 | P25: 3441 | Q25: 3799 | R25: 3802 | S25: 3928 | T25: 3957 | U25: 4258 | V25: 4805 | W25: 4926 | X25: 5011 | Y25: 4808 | Z25: 5413 | AA25: 5682 | AB25: 5460 | AC25: 5395 | AD25: 7469 | AE25: 8819 | AF25: 9833 | AG25: 9919 | AH25: 10566 | AI25: 10731 | AJ25: 10118 | AK25: 12637 | AL25: 15111 | AM25: 13907 | AN25: 14272 | AO25: 15470 | AP25: 13531 | AQ25: 15083 | AR25: 16105 | AS25: 17032 | AT25: 16696 | AU25: 14930 | AV25: 18750 | AW25: 20321 | AX25: 19411 | AY25: 19356 | AZ25: 19400
A26: Brazil | B26: 108051 | C26: 127741 | D26: 148672 | E26: 168803 | F26: 186095 | G26: 145819 | H26: 167583 | I26: 179166 | J26: 143652 | K26: 142957 | L26: 226938 | M26: 263256 | N26: 286539 | O26: 320105 | P26: 439434 | Q26: 455335 | R26: 399249 | S26: 382465 | T26: 429184 | U26: 546764 | V26: 770860 | W26: 851146 | X26: 883862 | Y26: 864307 | Z26: 599642 | AA26: 655454 | AB26: 559982 | AC26: 509798 | AD26: 558232 | AE26: 669290 | AF26: 891633 | AG26: 1107628 | AH26: 1397114 | AI26: 1695855 | AJ26: 1669204 | AK26: 2208704 | AL26: 2614027 | AM26: 2464053 | AN26: 2471718 | AO26: 2456055 | AP26: 1800046 | AQ26: 1796622 | AR26: 2063519 | AS26: 1916934 | AT26: 1873286 | AU26: 1476092 | AV26: 1670650 | AW26: 1951849 | AX26: 2191137 | AY26: 2171337 | AZ26: 2125958
A27: Brunei | B27: 1467 | C27: 1787 | D27: 2176 | E27: 2439 | F27: 3522 | L27: 5470 | M27: 3727 | N27: 4384 | O27: 4177 | P27: 4652 | Q27: 5574 | R27: 5949 | S27: 6256 | T27: 6327 | U27: 6795 | V27: 8098 | W27: 8156 | X27: 7974 | Y27: 6061 | Z27: 6544 | AA27: 6650 | AB27: 6206 | AC27: 6475 | AD27: 7266 | AE27: 8723 | AF27: 10561 | AG27: 12710 | AH27: 13571 | AI27: 15949 | AJ27: 11892 | AK27: 13707 | AL27: 18525 | AM27: 19048 | AN27: 18094 | AO27: 17098 | AP27: 12930 | AQ27: 11400 | AR27: 12128 | AS27: 13567 | AT27: 13469 | AU27: 12006 | AV27: 14006 | AW27: 16682 | AX27: 15095 | AY27: 15463 | AZ27: 16007
A28: Bulgaria | B28: 11908 | C28: 12625 | D28: 12908 | E28: 13982 | F28: 9408 | G28: 37751 | H28: 40718 | I28: 42467 | J28: 43641 | K28: 46358 | L28: 39692 | M28: 35130 | N28: 40721 | O28: 66546 | P28: 67774 | Q28: 29882 | R28: 2928 | S28: 11882 | T28: 6449 | U28: 11338 | V28: 18992 | W28: 12295 | X28: 11317 | Y28: 15031 | Z28: 13628 | AA28: 13246 | AB28: 14183 | AC28: 16403 | AD28: 21146 | AE28: 26158 | AF28: 29868 | AG28: 34380 | AH28: 44432 | AI28: 54476 | AJ28: 52024 | AK28: 50690 | AL28: 57682 | AM28: 54297 | AN28: 55820 | AO28: 57081 | AP28: 50766 | AQ28: 53929 | AR28: 59288 | AS28: 66318 | AT28: 68639 | AU28: 70658 | AV28: 84477 | AW28: 90719 | AX28: 102434 | AY28: 112232 | AZ28: 117007
A29: Burkina Faso | B29: 890 | C29: 853 | D29: 1031 | E29: 1328 | F29: 1782 | G29: 2386 | H29: 2076 | I29: 1934 | J29: 1767 | K29: 1579 | L29: 1746 | M29: 2290 | N29: 2665 | O29: 2942 | P29: 2942 | Q29: 3488 | R29: 3526 | S29: 3775 | T29: 3599 | U29: 2164 | V29: 2676 | W29: 2909 | X29: 2753 | Y29: 3155 | Z29: 3388 | AA29: 2961 | AB29: 3190 | AC29: 3620 | AD29: 4740 | AE29: 5449 | AF29: 6150 | AG29: 6548 | AH29: 7627 | AI29: 9450 | AJ29: 9440 | AK29: 10118 | AL29: 12078 | AM29: 12569 | AN29: 13444 | AO29: 13947 | AP29: 11833 | AQ29: 12829 | AR29: 14094 | AS29: 15916 | AT29: 16092 | AU29: 17837 | AV29: 19747 | AW29: 19588 | AX29: 21181 | AY29: 23975 | AZ29: 27056
A30: Burundi | B30: 414 | C30: 456 | D30: 542 | E30: 612 | F30: 791 | G30: 951 | H30: 989 | I30: 1045 | J30: 1106 | K30: 1005 | L30: 1170 | M30: 1233 | N30: 1161 | O30: 1088 | P30: 1131 | Q30: 1131 | R30: 1167 | S30: 1082 | T30: 938 | U30: 924 | V30: 1000 | W30: 868 | X30: 972 | Y30: 893 | Z30: 866 | AA30: 870 | AB30: 877 | AC30: 825 | AD30: 785 | AE30: 915 | AF30: 1117 | AG30: 1273 | AH30: 1356 | AI30: 1612 | AJ30: 1775 | AK30: 2032 | AL30: 2236 | AM30: 2333 | AN30: 2456 | AO30: 2706 | AP30: 3104 | AQ30: 2960 | AR30: 3172 | AS30: 3037 | AT30: 3009 | AU30: 3089 | AV30: 3356 | AW30: 3922 | AX30: 4246 | AY30: 4743 | AZ30: 6745
A31: Cambodia | B31: 746 | C31: 799 | D31: 738 | E31: 806 | F31: 768 | M31: 205 | N31: 141 | O31: 276 | P31: 346 | Q31: 898 | R31: 2007 | S31: 2435 | T31: 2422 | U31: 2760 | V31: 3430 | W31: 3509 | X31: 3462 | Y31: 3132 | Z31: 3522 | AA31: 3707 | AB31: 4154 | AC31: 4507 | AD31: 5054 | AE31: 5879 | AF31: 7058 | AG31: 8342 | AH31: 10117 | AI31: 12162 | AJ31: 12490 | AK31: 13796 | AL31: 16017 | AM31: 17829 | AN31: 19806 | AO31: 22040 | AP31: 24217 | AQ31: 26591 | AR31: 29394 | AS31: 33181 | AT31: 36682 | AU31: 34898 | AV31: 36797 | AW31: 39838 | AX31: 43304 | AY31: 47328 | AZ31: 49799
A32: Cameroon | B32: 3187 | C32: 3473 | D32: 4062 | E32: 5347 | F32: 7116 | G32: 8850 | H32: 10026 | I32: 9616 | J32: 9692 | K32: 10243 | L32: 10698 | M32: 13945 | N32: 16152 | O32: 16403 | P32: 14626 | Q32: 14641 | R32: 16325 | S32: 14963 | T32: 15611 | U32: 10622 | V32: 10075 | W32: 11227 | X32: 11352 | Y32: 11338 | Z32: 11553 | AA32: 10245 | AB32: 10950 | AC32: 12369 | AD32: 15944 | AE32: 18803 | AF32: 19534 | AG32: 20912 | AH32: 23931 | AI32: 27712 | AJ32: 27903 | AK32: 27530 | AL32: 30626 | AM32: 30174 | AN32: 33729 | AO32: 36396 | AP32: 32213 | AQ32: 33805 | AR32: 36086 | AS32: 39992 | AT32: 39673 | AU32: 40863 | AV32: 45036 | AW32: 44442 | AX32: 49283 | AY32: 52784 | AZ32: 56011
A33: Canada | B33: 170692 | C33: 202829 | D33: 207789 | E33: 214677 | F33: 238664 | G33: 276064 | H33: 307246 | I33: 314639 | J33: 341863 | K33: 356728 | L33: 366184 | M33: 379015 | N33: 433140 | O33: 509380 | P33: 567225 | Q33: 596089 | R33: 612514 | S33: 594376 | T33: 579059 | U33: 579913 | V33: 605941 | W33: 630598 | X33: 655010 | Y33: 634004 | Z33: 678417 | AA33: 744631 | AB33: 738968 | AC33: 760149 | AD33: 895599 | AE33: 1026473 | AF33: 1173505 | AG33: 1319356 | AH33: 1468896 | AI33: 1552864 | AJ33: 1376509 | AK33: 1617345 | AL33: 1793327 | AM33: 1828362 | AN33: 1846595 | AO33: 1805751 | AP33: 1556508 | AQ33: 1527996 | AR33: 1649266 | AS33: 1725300 | AT33: 1743725 | AU33: 1655685 | AV33: 2022382 | AW33: 2190411 | AX33: 2173340 | AY33: 2241253 | AZ33: 2225341
A34: Cape Verde | B34: 118 | C34: 110 | D34: 103 | E34: 119 | F34: 127 | G34: 157 | H34: 187 | I34: 149 | J34: 144 | K34: 146 | L34: 164 | M34: 212 | N34: 264 | O34: 322 | P34: 332 | Q34: 413 | R34: 443 | S34: 479 | T34: 431 | U34: 450 | V34: 570 | W34: 611 | X34: 609 | Y34: 648 | Z34: 693 | AA34: 699 | AB34: 791 | AC34: 867 | AD34: 1105 | AE34: 1263 | AF34: 1395 | AG34: 1452 | AH34: 1650 | AI34: 1960 | AJ34: 1852 | AK34: 1825 | AL34: 2047 | AM34: 1913 | AN34: 2029 | AO34: 2042 | AP34: 1750 | AQ34: 1850 | AR34: 1997 | AS34: 2205 | AT34: 2251 | AU34: 1831 | AV34: 2053 | AW34: 2309 | AX34: 2588 | AY34: 2726 | AZ34: 2786
A35: Central African Republic | B35: 528 | C35: 629 | D35: 708 | E35: 852 | F35: 977 | G35: 714 | H35: 743 | I35: 719 | J35: 690 | K35: 670 | L35: 883 | M35: 1158 | N35: 1275 | O35: 1372 | P35: 1354 | Q35: 1572 | R35: 1498 | S35: 1494 | T35: 1309 | U35: 858 | V35: 1117 | W35: 1000 | X35: 979 | Y35: 1036 | Z35: 1039 | AA35: 868 | AB35: 899 | AC35: 983 | AD35: 1188 | AE35: 1310 | AF35: 1413 | AG35: 1538 | AH35: 1755 | AI35: 2033 | AJ35: 2059 | AK35: 2141 | AL35: 2435 | AM35: 2512 | AN35: 1692 | AO35: 1896 | AP35: 1696 | AQ35: 1825 | AR35: 2072 | AS35: 2280 | AT35: 2279 | AU35: 2389 | AV35: 2585 | AW35: 2460 | AX35: 2602 | AY35: 2831 | AZ35: 2932
A36: Chad | B36: 876 | C36: 823 | D36: 832 | E36: 991 | F36: 894 | G36: 958 | H36: 1133 | I36: 1095 | J36: 1096 | K36: 1177 | L36: 1275 | M36: 1570 | N36: 1780 | O36: 2081 | P36: 1966 | Q36: 2369 | R36: 2347 | S36: 2446 | T36: 2138 | U36: 1732 | V36: 2123 | W36: 2360 | X36: 2268 | Y36: 2561 | Z36: 2256 | AA36: 2039 | AB36: 2512 | AC36: 2928 | AD36: 4025 | AE36: 6490 | AF36: 8660 | AG36: 9710 | AH36: 10867 | AI36: 13384 | AJ36: 12304 | AK36: 14070 | AL36: 16682 | AM36: 17904 | AN36: 17866 | AO36: 18149 | AP36: 14561 | AQ36: 13023 | AR36: 13344 | AS36: 15334 | AT36: 14906 | AU36: 14954 | AV36: 16881 | AW36: 17867 | AX36: 18343 | AY36: 19078 | AZ36: 18792
A37: Chile | B37: 7941 | C37: 10843 | D37: 14699 | E37: 16940 | F37: 22806 | G37: 29032 | H37: 34374 | I37: 25630 | J37: 20819 | K37: 20246 | L37: 17360 | M37: 18662 | N37: 22010 | O37: 25947 | P37: 29889 | Q37: 33231 | R37: 38249 | S37: 46597 | T37: 49855 | U37: 57517 | V37: 74119 | W37: 78575 | X37: 85730 | Y37: 81996 | Z37: 75596 | AA37: 78250 | AB37: 71517 | AC37: 70295 | AD37: 76508 | AE37: 99079 | AF37: 122315 | AG37: 153840 | AH37: 172565 | AI37: 179663 | AJ37: 171794 | AK37: 217105 | AL37: 251225 | AM37: 267165 | AN37: 277218 | AO37: 259394 | AP37: 242515 | AQ37: 249306 | AR37: 276357 | AS37: 295428 | AT37: 278040 | AU37: 254060 | AV37: 315411 | AW37: 301270 | AX37: 335627 | AY37: 330210 | AZ37: 343823
A38: China | B38: 160340 | C38: 150854 | D38: 171467 | E38: 214160 | F38: 263190 | G38: 303550 | H38: 289215 | I38: 285139 | J38: 306013 | K38: 314832 | L38: 310709 | M38: 301471 | N38: 328305 | O38: 409363 | P38: 458985 | Q38: 397359 | R38: 415946 | S38: 495515 | T38: 621918 | U38: 566297 | V38: 737654 | W38: 868770 | X38: 967886 | Y38: 1035510 | Z38: 1101134 | AA38: 1220337 | AB38: 1351372 | AC38: 1486618 | AD38: 1680942 | AE38: 1978937 | AF38: 2325515 | AG38: 2797286 | AH38: 3612210 | AI38: 4653314 | AJ38: 5176180 | AK38: 6138992 | AL38: 7624861 | AM38: 8682939 | AN38: 9782784 | AO38: 10701415 | AP38: 11307226 | AQ38: 11448003 | AR38: 12503299 | AS38: 14110963 | AT38: 14572410 | AU38: 15103357 | AV38: 18190803 | AW38: 18307816 | AX38: 18270351 | AY38: 18748009 | AZ38: 19231705
A39: Colombia | B39: 18508 | C39: 21674 | D39: 27519 | E39: 32864 | F39: 39497 | G39: 46501 | H39: 50661 | I39: 54252 | J39: 53920 | K39: 53257 | L39: 48581 | M39: 48648 | N39: 50640 | O39: 54592 | P39: 55048 | Q39: 56071 | R39: 57954 | S39: 68579 | T39: 77721 | U39: 97665 | V39: 110564 | W39: 116130 | X39: 127490 | Y39: 117725 | Z39: 103132 | AA39: 99270 | AB39: 97606 | AC39: 97353 | AD39: 94072 | AE39: 116382 | AF39: 145600 | AG39: 161793 | AH39: 206230 | AI39: 242504 | AJ39: 232469 | AK39: 286499 | AL39: 334966 | AM39: 370692 | AN39: 382094 | AO39: 381241 | AP39: 293493 | AQ39: 282720 | AR39: 311890 | AS39: 334124 | AT39: 323055 | AU39: 270348 | AV39: 318525 | AW39: 345632 | AX39: 366292 | AY39: 418542 | AZ39: 427766
A40: Comoros | B40: 60 | C40: 59 | D40: 65 | E40: 85 | F40: 113 | G40: 243 | H40: 213 | I40: 202 | J40: 196 | K40: 189 | L40: 192 | M40: 258 | N40: 313 | O40: 336 | P40: 329 | Q40: 402 | R40: 401 | S40: 437 | T40: 428 | U40: 315 | V40: 393 | W40: 392 | X40: 363 | Y40: 364 | Z40: 372 | AA40: 340 | AB40: 373 | AC40: 427 | AD40: 547 | AE40: 622 | AF40: 656 | AG40: 689 | AH40: 796 | AI40: 916 | AJ40: 904 | AK40: 909 | AL40: 1023 | AM40: 1016 | AN40: 1116 | AO40: 1150 | AP40: 966 | AQ40: 1013 | AR40: 1077 | AS40: 1179 | AT40: 1188 | AU40: 1218 | AV40: 1273 | AW40: 1223 | AX40: 1335 | AY40: 1456 | AZ40: 1548
...

Sheet Data for 1st chart
A1: Country | B1: 1975 | C1: 1976 | D1: 1977 | E1: 1978 | F1: 1979 | G1: 1980 | H1: 1981 | I1: 1982 | J1: 1983 | K1: 1984 | L1: 1985 | M1: 1986 | N1: 1987 | O1: 1988 | P1: 1989 | Q1: 1990 | R1: 1991 | S1: 1992 | T1: 1993 | U1: 1994 | V1: 1995 | W1: 1996 | X1: 1997 | Y1: 1998 | Z1: 1999 | AA1: 2000 | AB1: 2001 | AC1: 2002 | AD1: 2003 | AE1: 2004 | AF1: 2005 | AG1: 2006 | AH1: 2007 | AI1: 2008 | AJ1: 2009 | AK1: 2010 | AL1: 2011 | AM1: 2012 | AN1: 2013 | AO1: 2014 | AP1: 2015 | AQ1: 2016 | AR1: 2017 | AS1: 2018 | AT1: 2019 | AU1: 2020 | AV1: 2021 | AW1: 2022 | AX1: 2023 | AY1: 2024 | AZ1: 2025
A2: Angola | B2: 4147 | C2: 3981 | D2: 4344 | E2: 4845 | F2: 5380 | G2: 8730 | H2: 8170 | I2: 8170 | J2: 8514 | K2: 9025 | L2: 11119 | M2: 10411 | N2: 11900 | O2: 12909 | P2: 15017 | Q2: 16529 | R2: 16022 | S2: 12354 | T2: 8966 | U2: 6529 | V2: 8148 | W2: 10510 | X2: 12344 | Y2: 10464 | Z2: 9895 | AA2: 12646 | AB2: 12378 | AC2: 17312 | AD2: 20342 | AE2: 26998 | AF2: 41397 | AG2: 58654 | AH2: 73038 | AI2: 98790 | AJ2: 81705 | AK2: 95547 | AL2: 125552 | AM2: 143573 | AN2: 153761 | AO2: 164448 | AP2: 131661 | AQ2: 114764 | AR2: 139835 | AS2: 114189 | AT2: 94671 | AU2: 66521 | AV2: 84375 | AW2: 142442 | AX2: 109764 | AY2: 115946 | AZ2: 113343
A3: Antigua and Barbuda | B3: 85 | C3: 71 | D3: 81 | E3: 92 | F3: 113 | G3: 132 | H3: 149 | I3: 166 | J3: 185 | K3: 212 | L3: 246 | M3: 298 | N3: 347 | O3: 411 | P3: 455 | Q3: 479 | R3: 504 | S3: 525 | T3: 566 | U3: 625 | V3: 616 | W3: 679 | X3: 734 | Y3: 790 | Z3: 836 | AA3: 901 | AB3: 878 | AC3: 898 | AD3: 948 | AE3: 1026 | AF3: 1144 | AG3: 1304 | AH3: 1487 | AI3: 1558 | AJ3: 1387 | AK3: 1298 | AL3: 1287 | AM3: 1365 | AN3: 1325 | AO3: 1379 | AP3: 1437 | AQ3: 1490 | AR3: 1535 | AS3: 1662 | AT3: 1726 | AU3: 1412 | AV3: 1602 | AW3: 1867 | AX3: 2006 | AY3: 2225 | AZ3: 2373
A4: Armenia | S4: 108 | T4: 835 | U4: 648 | V4: 1287 | W4: 1597 | X4: 1639 | Y4: 1892 | Z4: 1845 | AA4: 1912 | AB4: 2118 | AC4: 2376 | AD4: 2807 | AE4: 3577 | AF4: 4900 | AG4: 6384 | AH4: 9206 | AI4: 11662 | AJ4: 8648 | AK4: 9260 | AL4: 10142 | AM4: 10619 | AN4: 11121 | AO4: 11610 | AP4: 10553 | AQ4: 10546 | AR4: 11527 | AS4: 12458 | AT4: 13619 | AU4: 12642 | AV4: 13879 | AW4: 19514 | AX4: 24086 | AY4: 25533 | AZ4: 26258
A5: Azerbaijan | S5: 1193 | T5: 1309 | U5: 2258 | V5: 2417 | W5: 3177 | X5: 4317 | Y5: 4280 | Z5: 4581 | AA5: 5273 | AB5: 5475 | AC5: 6232 | AD5: 7276 | AE5: 8682 | AF5: 13239 | AG5: 20983 | AH5: 33050 | AI5: 48852 | AJ5: 44297 | AK5: 52909 | AL5: 65952 | AM5: 69684 | AN5: 74164 | AO5: 75235 | AP5: 52997 | AQ5: 37830 | AR5: 41375 | AS5: 47113 | AT5: 48174 | AU5: 42693 | AV5: 54825 | AW5: 78807 | AX5: 72428 | AY5: 74316 | AZ5: 78870
A6: Bahrain | B6: 1185 | C6: 1705 | D6: 2144 | E6: 2449 | F6: 2920 | G6: 3745 | H6: 4228 | I6: 4445 | J6: 4554 | K6: 4727 | L6: 4460 | M6: 3490 | N6: 3780 | O6: 4672 | P6: 4873 | Q6: 5176 | R6: 5430 | S6: 5673 | T6: 6241 | U6: 6683 | V6: 7075 | W6: 7357 | X6: 7629 | Y6: 7293 | Z6: 7905 | AA6: 9448 | AB6: 9579 | AC6: 10001 | AD6: 11546 | AE6: 13709 | AF6: 16647 | AG6: 19291 | AH6: 22653 | AI6: 26803 | AJ6: 23913 | AK6: 26806 | AL6: 29915 | AM6: 31963 | AN6: 33823 | AO6: 34773 | AP6: 32523 | AQ6: 33885 | AR6: 37205 | AS6: 39568 | AT6: 40447 | AU6: 35838 | AV6: 40840 | AW6: 46458 | AX6: 46192 | AY6: 46943 | AZ6: 47829
A7: Bangladesh | B7: 8476 | C7: 9447 | D7: 9950 | E7: 12751 | F7: 14758 | G7: 24775 | H7: 26355 | I7: 24678 | J7: 23904 | K7: 26817 | L7: 28819 | M7: 29639 | N7: 32449 | O7: 34914 | P7: 38070 | Q7: 41068 | R7: 42488 | S7: 43292 | T7: 43684 | U7: 46438 | V7: 51842 | W7: 55445 | X7: 57599 | Y7: 59879 | Z7: 61526 | AA7: 61687 | AB7: 62537 | AC7: 65036 | AD7: 71755 | AE7: 77152 | AF7: 79530 | AG7: 86028 | AH7: 95374 | AI7: 109765 | AJ7: 122760 | AK7: 138094 | AL7: 154097 | AM7: 159749 | AN7: 179676 | AO7: 207102 | AP7: 233687 | AQ7: 265236 | AR7: 293755 | AS7: 321379 | AT7: 351238 | AU7: 373902 | AV7: 416265 | AW7: 460201 | AX7: 451534 | AY7: 451096 | AZ7: 467218
A8: Belarus | S8: 12800 | T8: 11408 | U8: 15687 | V8: 10532 | W8: 14494 | X8: 14091 | Y8: 15215 | Z8: 12133 | AA8: 10785 | AB8: 12778 | AC8: 15092 | AD8: 18420 | AE8: 23928 | AF8: 31239 | AG8: 38219 | AH8: 46815 | AI8: 62798 | AJ8: 50855 | AK8: 57220 | AL8: 61368 | AM8: 65669 | AN8: 75496 | AO8: 78736 | AP8: 56329 | AQ8: 47703 | AR8: 54723 | AS8: 60011 | AT8: 64414 | AU8: 61312 | AV8: 68207 | AW8: 73735 | AX8: 71792 | AY8: 71180 | AZ8: 71561
A9: Belize | B9: 104 | C9: 82 | D9: 106 | E9: 121 | F9: 141 | G9: 229 | H9: 238 | I9: 238 | J9: 251 | K9: 280 | L9: 278 | M9: 303 | N9: 354 | O9: 418 | P9: 482 | Q9: 547 | R9: 597 | S9: 696 | T9: 753 | U9: 772 | V9: 819 | W9: 851 | X9: 873 | Y9: 929 | Z9: 1000 | AA9: 1139 | AB9: 1173 | AC9: 1245 | AD9: 1309 | AE9: 1401 | AF9: 1475 | AG9: 1591 | AH9: 1707 | AI9: 1739 | AJ9: 1688 | AK9: 1746 | AL9: 1827 | AM9: 1909 | AN9: 2033 | AO9: 2138 | AP9: 2193 | AQ9: 2240 | AR9: 2266 | AS9: 2293 | AT9: 2388 | AU9: 2043 | AV9: 2421 | AW9: 2847 | AX9: 3067 | AY9: 3427 | AZ9: 3611
A10: Bosnia and Herzegovina | W10: 3584 | X10: 4578 | Y10: 5281 | Z10: 5766 | AA10: 5568 | AB10: 5801 | AC10: 6728 | AD10: 8499 | AE10: 10157 | AF10: 11223 | AG10: 12865 | AH10: 15779 | AI10: 19113 | AJ10: 17614 | AK10: 17176 | AL10: 18644 | AM10: 17227 | AN10: 18179 | AO10: 18559 | AP10: 16404 | AQ10: 17117 | AR10: 18326 | AS10: 20484 | AT10: 20483 | AU10: 20226 | AV10: 23673 | AW10: 24535 | AX10: 27592 | AY10: 28795 | AZ10: 28807
A11: Brunei | B11: 1467 | C11: 1787 | D11: 2176 | E11: 2439 | F11: 3522 | L11: 5470 | M11: 3727 | N11: 4384 | O11: 4177 | P11: 4652 | Q11: 5574 | R11: 5949 | S11: 6256 | T11: 6327 | U11: 6795 | V11: 8098 | W11: 8156 | X11: 7974 | Y11: 6061 | Z11: 6544 | AA11: 6650 | AB11: 6206 | AC11: 6475 | AD11: 7266 | AE11: 8723 | AF11: 10561 | AG11: 12710 | AH11: 13571 | AI11: 15949 | AJ11: 11892 | AK11: 13707 | AL11: 18525 | AM11: 19048 | AN11: 18094 | AO11: 17098 | AP11: 12930 | AQ11: 11400 | AR11: 12128 | AS11: 13567 | AT11: 13469 | AU11: 12006 | AV11: 14006 | AW11: 16682 | AX11: 15095 | AY11: 15463 | AZ11: 16007
A12: Cape Verde | B12: 118 | C12: 110 | D12: 103 | E12: 119 | F12: 127 | G12: 157 | H12: 187 | I12: 149 | J12: 144 | K12: 146 | L12: 164 | M12: 212 | N12: 264 | O12: 322 | P12: 332 | Q12: 413 | R12: 443 | S12: 479 | T12: 431 | U12: 450 | V12: 570 | W12: 611 | X12: 609 | Y12: 648 | Z12: 693 | AA12: 699 | AB12: 791 | AC12: 867 | AD12: 1105 | AE12: 1263 | AF12: 1395 | AG12: 1452 | AH12: 1650 | AI12: 1960 | AJ12: 1852 | AK12: 1825 | AL12: 2047 | AM12: 1913 | AN12: 2029 | AO12: 2042 | AP12: 1750 | AQ12: 1850 | AR12: 1997 | AS12: 2205 | AT12: 2251 | AU12: 1831 | AV12: 2053 | AW12: 2309 | AX12: 2588 | AY12: 2726 | AZ12: 2786
A13: Comoros | B13: 60 | C13: 59 | D13: 65 | E13: 85 | F13: 113 | G13: 243 | H13: 213 | I13: 202 | J13: 196 | K13: 189 | L13: 192 | M13: 258 | N13: 313 | O13: 336 | P13: 329 | Q13: 402 | R13: 401 | S13: 437 | T13: 428 | U13: 315 | V13: 393 | W13: 392 | X13: 363 | Y13: 364 | Z13: 372 | AA13: 340 | AB13: 373 | AC13: 427 | AD13: 547 | AE13: 622 | AF13: 656 | AG13: 689 | AH13: 796 | AI13: 916 | AJ13: 904 | AK13: 909 | AL13: 1023 | AM13: 1016 | AN13: 1116 | AO13: 1150 | AP13: 966 | AQ13: 1013 | AR13: 1077 | AS13: 1179 | AT13: 1188 | AU13: 1218 | AV13: 1273 | AW13: 1223 | AX13: 1335 | AY13: 1456 | AZ13: 1548
A14: Croatia | S14: 568 | T14: 7358 | U14: 16669 | V14: 20657 | W14: 22104 | X14: 22101 | Y14: 23971 | Z14: 23593 | AA14: 22145 | AB14: 23067 | AC14: 26739 | AD14: 35239 | AE14: 41820 | AF14: 45035 | AG14: 49593 | AH14: 59303 | AI14: 68469 | AJ14: 62255 | AK14: 59032 | AL14: 62889 | AM14: 57585 | AN14: 59854 | AO14: 59628 | AP14: 51012 | AQ14: 52640 | AR14: 56166 | AS14: 61694 | AT14: 61472 | AU14: 57919 | AV14: 69055 | AW14: 71260 | AX14: 84416 | AY14: 92506 | AZ14: 98951
A15: Djibouti | B15: 157 | C15: 187 | D15: 201 | E15: 221 | F15: 264 | R15: 650 | S15: 672 | T15: 655 | U15: 691 | V15: 699 | W15: 694 | X15: 706 | Y15: 722 | Z15: 759 | AA15: 781 | AB15: 811 | AC15: 837 | AD15: 882 | AE15: 936 | AF15: 996 | AG15: 1080 | AH15: 1191 | AI15: 1382 | AJ15: 1426 | AK15: 1544 | AL15: 1740 | AM15: 1901 | AN15: 2044 | AO15: 2221 | AP15: 2424 | AQ15: 2605 | AR15: 2763 | AS15: 2913 | AT15: 3089 | AU15: 3144 | AV15: 3393 | AW15: 3563 | AX15: 3917 | AY15: 4257 | AZ15: 4587
A16: Dominica | B16: 40 | C16: 39 | D16: 44 | E16: 54 | F16: 53 | G16: 73 | H16: 82 | I16: 90 | J16: 99 | K16: 109 | L16: 119 | M16: 135 | N16: 152 | O16: 171 | P16: 185 | Q16: 201 | R16: 220 | S16: 234 | T16: 246 | U16: 264 | V16: 275 | W16: 292 | X16: 303 | Y16: 322 | Z16: 332 | AA16: 333 | AB16: 340 | AC16: 333 | AD16: 343 | AE16: 367 | AF16: 364 | AG16: 390 | AH16: 421 | AI16: 458 | AJ16: 489 | AK16: 494 | AL16: 501 | AM16: 486 | AN16: 498 | AO16: 520 | AP16: 541 | AQ16: 576 | AR16: 522 | AS16: 555 | AT16: 612 | AU16: 504 | AV16: 555 | AW16: 607 | AX16: 654 | AY16: 697 | AZ16: 742
A17: Dominican Republic | B17: 4439 | C17: 4874 | D17: 5658 | E17: 5839 | F17: 6782 | G17: 8672 | H17: 9698 | I17: 9141 | J17: 9461 | K17: 14870 | L17: 6496 | M17: 7891 | N17: 8305 | O17: 7605 | P17: 8589 | Q17: 7995 | R17: 9887 | S17: 11605 | T17: 13081 | U17: 14645 | V17: 16637 | W17: 18242 | X17: 20017 | Y17: 21672 | Z17: 22137 | AA17: 24306 | AB17: 25602 | AC17: 27249 | AD17: 21518 | AE17: 22506 | AF17: 35948 | AG17: 37998 | AH17: 44067 | AI17: 48174 | AJ17: 48281 | AK17: 53862 | AL17: 58006 | AM17: 60627 | AN17: 62631 | AO17: 67098 | AP17: 71056 | AQ17: 75625 | AR17: 79153 | AS17: 85068 | AT17: 89237 | AU17: 78625 | AV17: 95067 | AW17: 113813 | AX17: 120794 | AY17: 124613 | AZ17: 127828
A18: Eritrea | S18: 606 | T18: 374 | U18: 433 | V18: 483 | W18: 579 | X18: 594 | Y18: 626 | Z18: 614 | AA18: 547 | AB18: 582 | AC18: 564 | AD18: 673 | AE18: 858 | AF18: 850 | AG18: 937 | AH18: 1020 | AI18: 923 | AJ18: 1297 | AK18: 1590 | AL18: 2065 | AM18: 2255 | AN18: 1958 | AO18: 2604 | AP18: 2016 | AQ18: 2213 | AR18: 1904 | AS18: 2006 | AT18: 1982 | AU18: 1982
A19: Georgia | U19: 850 | V19: 1961 | W19: 3148 | X19: 3608 | Y19: 3730 | Z19: 2898 | AA19: 3144 | AB19: 3311 | AC19: 3493 | AD19: 4103 | AE19: 5269 | AF19: 6590 | AG19: 7979 | AH19: 10458 | AI19: 13158 | AJ19: 11069 | AK19: 12425 | AL19: 15475 | AM19: 16894 | AN19: 17516 | AO19: 17966 | AP19: 15223 | AQ19: 15445 | AR19: 16472 | AS19: 17905 | AT19: 17645 | AU19: 16013 | AV19: 18849 | AW19: 24985 | AX19: 30778 | AY19: 33775 | AZ19: 35353
A20: Grenada | B20: 44 | C20: 44 | D20: 50 | E20: 64 | F20: 75 | G20: 111 | H20: 116 | I20: 125 | J20: 132 | K20: 146 | L20: 168 | M20: 188 | N20: 215 | O20: 236 | P20: 267 | Q20: 278 | R20: 301 | S20: 310 | T20: 310 | U20: 325 | V20: 342 | W20: 367 | X20: 392 | Y20: 446 | Z20: 482 | AA20: 520 | AB20: 520 | AC20: 540 | AD20: 591 | AE20: 599 | AF20: 695 | AG20: 699 | AH20: 759 | AI20: 826 | AJ20: 771 | AK20: 771 | AL20: 779 | AM20: 800 | AN20: 843 | AO20: 911 | AP20: 997 | AQ20: 1062 | AR20: 1126 | AS20: 1167 | AT20: 1213 | AU20: 1043 | AV20: 1123 | AW20: 1231 | AX20: 1325 | AY20: 1392 | AZ20: 1464
A21: Guinea-Bissau | B21: 556 | C21: 500 | D21: 430 | E21: 497 | F21: 544 | G21: 289 | H21: 370 | I21: 421 | J21: 475 | K21: 330 | L21: 485 | M21: 474 | N21: 401 | O21: 374 | P21: 449 | Q21: 548 | R21: 772 | S21: 846 | T21: 653 | U21: 361 | V21: 778 | W21: 741 | X21: 704 | Y21: 592 | Z21: 580 | AA21: 392 | AB21: 413 | AC21: 466 | AD21: 553 | AE21: 582 | AF21: 640 | AG21: 635 | AH21: 753 | AI21: 953 | AJ21: 889 | AK21: 941 | AL21: 1157 | AM21: 1050 | AN21: 1110 | AO21: 1136 | AP21: 1153 | AQ21: 1245 | AR21: 1469 | AS21: 1555 | AT21: 1487 | AU21: 1523 | AV21: 1722 | AW21: 1721 | AX21: 2005 | AY21: 2184 | AZ21: 2274
A22: Kazakhstan | S22: 2875 | T22: 5152 | U22: 11881 | V22: 16639 | W22: 21035 | X22: 22166 | Y22: 22135 | Z22: 16871 | AA22: 18292 | AB22: 22153 | AC22: 24637 | AD22: 30834 | AE22: 43152 | AF22: 57125 | AG22: 81003 | AH22: 104850 | AI22: 133442 | AJ22: 115309 | AK22: 148047 | AL22: 192626 | AM22: 207999 | AN22: 236635 | AO22: 221416 | AP22: 184388 | AQ22: 137278 | AR22: 166806 | AS22: 179340 | AT22: 181667 | AU22: 171082 | AV22: 197112 | AW22: 225496 | AX22: 261840 | AY22: 284810 | AZ22: 300538
A23: Kiribati | B23: 80 | C23: 60 | D23: 56 | E23: 65 | F23: 62 | G23: 33 | H23: 35 | I23: 33 | J23: 31 | K23: 34 | L23: 26 | M23: 26 | N23: 30 | O23: 38 | P23: 38 | Q23: 37 | R23: 41 | S23: 62 | T23: 59 | U23: 67 | V23: 69 | W23: 81 | X23: 80 | Y23: 75 | Z23: 77 | AA23: 75 | AB23: 65 | AC23: 75 | AD23: 97 | AE23: 104 | AF23: 114 | AG23: 112 | AH23: 138 | AI23: 150 | AJ23: 142 | AK23: 166 | AL23: 196 | AM23: 207 | AN23: 202 | AO23: 201 | AP23: 192 | AQ23: 207 | AR23: 223 | AS23: 234 | AT23: 217 | AU23: 222 | AV23: 285 | AW23: 271 | AX23: 289 | AY23: 308 | AZ23: 312
A24: Kosovo | AA24: 2217 | AB24: 2509 | AC24: 2730 | AD24: 3390 | AE24: 3710 | AF24: 3828 | AG24: 4019 | AH24: 4868 | AI24: 5202 | AJ24: 5030 | AK24: 5348 | AL24: 6340 | AM24: 6167 | AN24: 6735 | AO24: 7076 | AP24: 6296 | AQ24: 6681 | AR24: 7178 | AS24: 7882 | AT24: 7900 | AU24: 7728 | AV24: 9418 | AW24: 9375 | AX24: 10470 | AY24: 11151 | AZ24: 11274
A25: Kyrgyzstan | S25: 917 | T25: 665 | U25: 1108 | V25: 1493 | W25: 1822 | X25: 1767 | Y25: 1630 | Z25: 1242 | AA25: 1368 | AB25: 1525 | AC25: 1606 | AD25: 1920 | AE25: 2214 | AF25: 2459 | AG25: 2837 | AH25: 3807 | AI25: 5139 | AJ25: 4690 | AK25: 4794 | AL25: 6198 | AM25: 6604 | AN25: 7335 | AO25: 7467 | AP25: 6678 | AQ25: 6813 | AR25: 7703 | AS25: 8271 | AT25: 9372 | AU25: 8283 | AV25: 9256 | AW25: 12269 | AX25: 15187 | AY25: 17491 | AZ25: 19849
A26: Latvia | S26: 1641 | T26: 2643 | U26: 4391 | V26: 5242 | W26: 5799 | X26: 6351 | Y26: 6977 | Z26: 7325 | AA26: 7765 | AB26: 8192 | AC26: 9256 | AD26: 11249 | AE26: 13831 | AF26: 16332 | AG26: 20453 | AH26: 29463 | AI26: 34296 | AJ26: 25758 | AK26: 23509 | AL26: 26832 | AM26: 27136 | AN26: 29157 | AO26: 30285 | AP26: 26347 | AQ26: 27110 | AR26: 29381 | AS26: 33263 | AT26: 33103 | AU26: 33353 | AV26: 38209 | AW26: 38045 | AX26: 42584 | AY26: 43508 | AZ26: 45535
A27: Lithuania | V27: 6742 | W27: 8440 | X27: 10159 | Y27: 11284 | Z27: 11017 | AA27: 11541 | AB27: 12260 | AC27: 14283 | AD27: 18801 | AE27: 22710 | AF27: 26118 | AG27: 30138 | AH27: 39765 | AI27: 48004 | AJ27: 37591 | AK27: 36693 | AL27: 43201 | AM27: 42736 | AN27: 46321 | AO27: 48388 | AP27: 41548 | AQ27: 42952 | AR27: 47745 | AS27: 54294 | AT27: 55132 | AU27: 57352 | AV27: 67068 | AW27: 71082 | AX27: 79824 | AY27: 84847 | AZ27: 89192
A28: Moldova | S28: 864 | T28: 1110 | U28: 1158 | V28: 1441 | W28: 1694 | X28: 1928 | Y28: 1697 | Z28: 1172 | AA28: 1315 | AB28: 1481 | AC28: 1662 | AD28: 1981 | AE28: 2598 | AF28: 2988 | AG28: 3408 | AH28: 4401 | AI28: 6055 | AJ28: 5438 | AK28: 6977 | AL28: 8417 | AM28: 8708 | AN28: 9496 | AO28: 9402 | AP28: 7778 | AQ28: 7981 | AR28: 9515 | AS28: 11252 | AT28: 11737 | AU28: 11530 | AV28: 13694 | AW28: 14493 | AX28: 16751 | AY28: 18126 | AZ28: 19462
A29: Montenegro | AA29: 966 | AB29: 1150 | AC29: 1269 | AD29: 1681 | AE29: 2073 | AF29: 2261 | AG29: 2724 | AH29: 3686 | AI29: 4564 | AJ29: 4171 | AK29: 4146 | AL29: 4544 | AM29: 4090 | AN29: 4466 | AO29: 4595 | AP29: 4055 | AQ29: 4376 | AR29: 4855 | AS29: 5509 | AT29: 5543 | AU29: 4777 | AV29: 5865 | AW29: 6243 | AX29: 7532 | AY29: 8023 | AZ29: 8562
A30: Mozambique | B30: 4841 | C30: 4409 | D30: 4463 | E30: 4663 | F30: 4903 | G30: 4615 | H30: 3585 | I30: 3662 | J30: 3280 | K30: 3417 | L30: 4516 | M30: 5301 | N30: 2395 | O30: 2105 | P30: 2199 | Q30: 3529 | R30: 3855 | S30: 2799 | T30: 2883 | U30: 2958 | V30: 3062 | W30: 4030 | X30: 4874 | Y30: 5551 | Z30: 6285 | AA30: 5931 | AB30: 5650 | AC30: 5951 | AD30: 6584 | AE30: 7937 | AF30: 8868 | AG30: 9510 | AH30: 10811 | AI30: 12920 | AJ30: 12264 | AK30: 11412 | AL30: 14619 | AM30: 16688 | AN30: 17198 | AO30: 17978 | AP30: 16209 | AQ30: 12069 | AR30: 13265 | AS30: 15017 | AT30: 15513 | AU30: 14235 | AV30: 16168 | AW30: 18884 | AX30: 20954 | AY30: 21944 | AZ30: 23771
A31: Namibia | B31: 1169 | C31: 1123 | D31: 1248 | E31: 1438 | F31: 1777 | Q31: 2568 | R31: 2841 | S31: 3296 | T31: 3156 | U31: 3537 | V31: 3948 | W31: 3954 | X31: 4110 | Y31: 3832 | Z31: 3824 | AA31: 3941 | AB31: 3577 | AC31: 3396 | AD31: 4974 | AE31: 6673 | AF31: 7324 | AG31: 7711 | AH31: 8730 | AI31: 8496 | AJ31: 8915 | AK31: 11281 | AL31: 12423 | AM31: 13016 | AN31: 12168 | AO31: 12434 | AP31: 11450 | AQ31: 10719 | AR31: 12883 | AS31: 13676 | AT31: 12539 | AU31: 10583 | AV31: 12399 | AW31: 12564 | AX31: 12402 | AY31: 13370 | AZ31: 14214
A32: Palau | B32: 15 | C32: 16 | D32: 17 | E32: 19 | F32: 21 | AA32: 150 | AB32: 159 | AC32: 163 | AD32: 155 | AE32: 166 | AF32: 186 | AG32: 191 | AH32: 196 | AI32: 199 | AJ32: 184 | AK32: 184 | AL32: 195 | AM32: 215 | AN32: 226 | AO32: 245 | AP32: 283 | AQ32: 303 | AR32: 290 | AS32: 288 | AT32: 282 | AU32: 259 | AV32: 236 | AW32: 248 | AX32: 275 | AY32: 306 | AZ32: 333
A33: Papua New Guinea | B33: 1536 | C33: 1652 | D33: 1819 | E33: 2211 | F33: 2543 | G33: 4087 | H33: 4011 | I33: 3805 | J33: 3799 | K33: 3509 | L33: 3250 | M33: 3535 | N33: 3885 | O33: 5400 | P33: 5238 | Q33: 4757 | R33: 5596 | S33: 6466 | T33: 7349 | U33: 8077 | V33: 7149 | W33: 7608 | X33: 7272 | Y33: 5558 | Z33: 5072 | AA33: 5169 | AB33: 4531 | AC33: 4387 | AD33: 5488 | AE33: 6279 | AF33: 7339 | AG33: 8355 | AH33: 9545 | AI33: 11671 | AJ33: 11619 | AK33: 14251 | AL33: 17985 | AM33: 21295 | AN33: 21261 | AO33: 23211 | AP33: 21723 | AQ33: 20759 | AR33: 22743 | AS33: 24110 | AT33: 24751 | AU33: 23848 | AV33: 26113 | AW33: 31653 | AX33: 30729 | AY33: 31654 | AZ33: 32835
A34: Qatar | B34: 2470 | C34: 3206 | D34: 3509 | E34: 3932 | F34: 5633 | G34: 6665 | H34: 7374 | I34: 6467 | J34: 5506 | K34: 5708 | L34: 5339 | M34: 4214 | N34: 4441 | O34: 4260 | P34: 4502 | Q34: 6266 | R34: 5579 | S34: 6384 | T34: 5804 | U34: 5946 | V34: 6861 | W34: 7761 | X34: 9976 | Y34: 8488 | Z34: 11266 | AA34: 18085 | AB34: 17498 | AC34: 19334 | AD34: 23716 | AE34: 30651 | AF34: 44636 | AG34: 58629 | AH34: 75987 | AI34: 112621 | AJ34: 88196 | AK34: 119707 | AL34: 167775 | AM34: 186834 | AN34: 198728 | AO34: 206225 | AP34: 161740 | AQ34: 151732 | AR34: 161099 | AS34: 183335 | AT34: 176371 | AU34: 144411 | AV34: 179732 | AW34: 235709 | AX34: 213003 | AY34: 221452 | AZ34: 222776
A35: Russia | S35: 71603 | T35: 196227 | U35: 293768 | V35: 335777 | W35: 412685 | X35: 433704 | Y35: 287672 | Z35: 209657 | AA35: 278264 | AB35: 328475 | AC35: 370062 | AD35: 461518 | AE35: 633294 | AF35: 817717 | AG35: 1060901 | AH35: 1393416 | AI35: 1779109 | AJ35: 1307927 | AK35: 1633111 | AL35: 2046621 | AM35: 2191486 | AN35: 2288428 | AO35: 2048837 | AP35: 1356703 | AQ35: 1280648 | AR35: 1575140 | AS35: 1653005 | AT35: 1695724 | AU35: 1488118 | AV35: 1828927 | AW35: 2295527 | AX35: 2059762 | AY35: 2161205 | AZ35: 2076396
A36: Saint Kitts and Nevis | B36: 43 | C36: 37 | D36: 38 | E36: 43 | F36: 50 | G36: 58 | H36: 69 | I36: 79 | J36: 78 | K36: 91 | L36: 101 | M36: 119 | N36: 136 | O36: 161 | P36: 179 | Q36: 203 | R36: 201 | S36: 223 | T36: 243 | U36: 272 | V36: 293 | W36: 312 | X36: 351 | Y36: 366 | Z36: 389 | AA36: 421 | AB36: 458 | AC36: 481 | AD36: 469 | AE36: 507 | AF36: 547 | AG36: 644 | AH36: 689 | AI36: 778 | AJ36: 774 | AK36: 779 | AL36: 836 | AM36: 825 | AN36: 875 | AO36: 953 | AP36: 957 | AQ36: 1007 | AR36: 1058 | AS36: 1076 | AT36: 1107 | AU36: 884 | AV36: 859 | AW36: 981 | AX36: 1056 | AY36: 1117 | AZ36: 1129
A37: Saint Lucia | B37: 71 | C37: 73 | D37: 81 | E37: 95 | F37: 115 | G37: 170 | H37: 194 | I37: 183 | J37: 197 | K37: 251 | L37: 284 | M37: 340 | N37: 375 | O37: 429 | P37: 486 | Q37: 579 | R37: 613 | S37: 674 | T37: 684 | U37: 713 | V37: 762 | W37: 788 | X37: 805 | Y37: 877 | Z37: 921 | AA37: 932 | AB37: 892 | AC37: 899 | AD37: 987 | AE37: 1066 | AF37: 1135 | AG37: 1268 | AH37: 1331 | AI37: 1427 | AJ37: 1400 | AK37: 1483 | AL37: 1569 | AM37: 1598 | AN37: 1660 | AO37: 1749 | AP37: 1808 | AQ37: 1869 | AR37: 1999 | AS37: 2061 | AT37: 2095 | AU37: 1499 | AV37: 1867 | AW37: 2343 | AX37: 2430 | AY37: 2523 | AZ37: 2632
A38: Saint Vincent and the Grenadines | B38: 38 | C38: 37 | D38: 43 | E38: 54 | F38: 63 | G38: 89 | H38: 110 | I38: 123 | J38: 132 | K38: 146 | L38: 157 | M38: 173 | N38: 189 | O38: 216 | P38: 232 | Q38: 259 | R38: 275 | S38: 300 | T38: 309 | U38: 312 | V38: 341 | W38: 358 | X38: 375 | Y38: 403 | Z38: 421 | AA38: 427 | AB38: 461 | AC38: 488 | AD38: 508 | AE38: 549 | AF38: 580 | AG38: 643 | AH38: 713 | AI38: 731 | AJ38: 714 | AK38: 720 | AL38: 713 | AM38: 727 | AN38: 766 | AO38: 771 | AP38: 786 | AQ38: 814 | AR38: 844 | AS38: 884 | AT38: 910 | AU38: 864 | AV38: 888 | AW38: 970 | AX38: 1071 | AY38: 1162 | AZ38: 1242
A39: Serbia | AA39: 10431 | AB39: 13650 | AC39: 17997 | AD39: 23627 | AE39: 26718 | AF39: 28143 | AG39: 33421 | AH39: 45121 | AI39: 54117 | AJ39: 46949 | AK39: 43067 | AL39: 51274 | AM39: 45111 | AN39: 50456 | AO39: 49114 | AP39: 41297 | AQ39: 42225 | AR39: 45973 | AS39: 52788 | AT39: 53865 | AU39: 55874 | AV39: 65830 | AW39: 66798 | AX39: 81343 | AY39: 89074 | AZ39: 92549
A40: Seychelles | B40: 59 | C40: 61 | D40: 80 | E40: 106 | F40: 157 | G40: 147 | H40: 154 | I40: 148 | J40: 147 | K40: 151 | L40: 169 | M40: 208 | N40: 249 | O40: 284 | P40: 305 | Q40: 369 | R40: 374 | S40: 434 | T40: 474 | U40: 486 | V40: 508 | W40: 503 | X40: 563 | Y40: 608 | Z40: 623 | AA40: 615 | AB40: 622 | AC40: 698 | AD40: 706 | AE40: 839 | AF40: 919 | AG40: 1016 | AH40: 1034 | AI40: 998 | AJ40: 847 | AK40: 970 | AL40: 1018 | AM40: 1060 | AN40: 1328 | AO40: 1388 | AP40: 1432 | AQ40: 1568 | AR40: 1675 | AS40: 1777 | AT40: 1867 | AU40: 1384 | AV40: 1490 | AW40: 2018 | AX40: 2187 | AY40: 2168 | AZ40: 2198
...

Sheet Rough for 1st chart
B1: FIND, LEN and MID | C1: Country
A2: March 26, 1971: Bangladesh | B2: =FIND(":",A2)+LEN(": ") -> 17 | C2: =MID(A2,B2,LEN(A2)) -> Bangladesh
A3: August 15, 1971: Bahrain | B3: =FIND(":",A3)+LEN(": ") -> 18 | C3: =MID(A3,B3,LEN(A3)) -> Bahrain | E3: year | F3: 1975 | G3: 1976 | H3: 1977 | I3: 1978 | J3: 1979 | K3: 1980 | L3: 1981 | M3: 1982 | N3: 1983 | O3: 1984 | P3: 1985 | Q3: 1986 | R3: 1987 | S3: 1988 | T3: 1989 | U3: 1990 | V3: 1991 | W3: 1992 | X3: 1993 | Y3: 1994 | Z3: 1995 | AA3: 1996 | AB3: 1997 | AC3: 1998 | AD3: 1999 | AE3: 2000 | AF3: 2001 | AG3: 2002 | AH3: 2003 | AI3: 2004 | AJ3: 2005 | AK3: 2006 | AL3: 2007 | AM3: 2008 | AN3: 2009 | AO3: 2010 | AP3: 2011 | AQ3: 2012 | AR3: 2013 | AS3: 2014 | AT3: 2015 | AU3: 2016 | AV3: 2017 | AW3: 2018 | AX3: 2019 | AY3: 2020 | AZ3: 2021 | BA3: 2022 | BB3: 2023 | BC3: 2024 | BD3: 2025
A4: September 3, 1971: Qatar | B4: =FIND(":",A4)+LEN(": ") -> 20 | C4: =MID(A4,B4,LEN(A4)) -> Qatar | E4: =GDP_Dashboard!$F$7 -> Angola | F4: =SUMIF('Data for 1st chart'!$A$2:$A$52, GDP_Dashboard!$F$7, 'Data for 1st chart'!B2:AZ2) -> 4147 | G4: =SUMIF('Data for 1st chart'!$A$2:$A$52, GDP_Dashboard!$F$7, 'Data for 1st chart'!C2:BA2) -> 3981 | H4: =SUMIF('Data for 1st chart'!$A$2:$A$52, GDP_Dashboard!$F$7, 'Data for 1st chart'!D2:BB2) -> 4344 | I4: =SUMIF('Data for 1st chart'!$A$2:$A$52, GDP_Dashboard!$F$7, 'Data for 1st chart'!E2:BC2) -> 4845 | J4: =SUMIF('Data for 1st chart'!$A$2:$A$52, GDP_Dashboard!$F$7, 'Data for 1st chart'!F2:BD2) -> 5380 | K4: =SUMIF('Data for 1st chart'!$A$2:$A$52, GDP_Dashboard!$F$7, 'Data for 1st chart'!G2:BE2) -> 8730 | L4: =SUMIF('Data for 1st chart'!$A$2:$A$52, GDP_Dashboard!$F$7, 'Data for 1st chart'!H2:BF2) -> 8170 | M4: =SUMIF('Data for 1st chart'!$A$2:$A$52, GDP_Dashboard!$F$7, 'Data for 1st chart'!I2:BG2) -> 8170 | ... BD4: =SUMIF('Data for 1st chart'!$A$2:$A$52, GDP_Dashboard!$F$7, 'Data for 1st chart'!AZ2:CX2) -> 113343
A5: November 2, 1971: The United Arab Emirates | B5: =FIND(":",A5)+LEN(": ") -> 19 | C5: =MID(A5,B5,LEN(A5)) -> The United Arab Emirates | E5: Bangladesh | F5: 8476 | G5: 9447 | H5: 9950 | I5: 12751 | J5: 14758 | K5: 24775 | L5: 26355 | M5: 24678 | N5: 23904 | O5: 26817 | P5: 28819 | Q5: 29639 | R5: 32449 | S5: 34914 | T5: 38070 | U5: 41068 | V5: 42488 | W5: 43292 | X5: 43684 | Y5: 46438 | Z5: 51842 | AA5: 55445 | AB5: 57599 | AC5: 59879 | AD5: 61526 | AE5: 61687 | AF5: 62537 | AG5: 65036 | AH5: 71755 | AI5: 77152 | AJ5: 79530 | AK5: 86028 | AL5: 95374 | AM5: 109765 | AN5: 122760 | AO5: 138094 | AP5: 154097 | AQ5: 159749 | AR5: 179676 | AS5: 207102 | AT5: 233687 | AU5: 265236 | AV5: 293755 | AW5: 321379 | AX5: 351238 | AY5: 373902 | AZ5: 416265 | BA5: 460201 | BB5: 451534 | BC5: 451096 | BD5: 467218
A6: July 10, 1973: The Bahamas | B6: =FIND(":",A6)+LEN(": ") -> 16 | C6: =MID(A6,B6,LEN(A6)) -> The Bahamas
A7: September 24, 1973: Guinea-Bissau | B7: =FIND(":",A7)+LEN(": ") -> 21 | C7: =MID(A7,B7,LEN(A7)) -> Guinea-Bissau | E7: average for other country | F7: =AVERAGE(AY4:BD4) -> 105398.5
A8: February 7, 1974: Grenada | B8: =FIND(":",A8)+LEN(": ") -> 19 | C8: =MID(A8,B8,LEN(A8)) -> Grenada | E8: average for bangladesh | F8: =AVERAGE(AY5:BD5) -> 436702.67
A9: June 25, 1975: Mozambique | B9: =FIND(":",A9)+LEN(": ") -> 16 | C9: =MID(A9,B9,LEN(A9)) -> Mozambique
A10: July 5, 1975: Cape Verde | B10: =FIND(":",A10)+LEN(": ") -> 15 | C10: =MID(A10,B10,LEN(A10)) -> Cape Verde
A11: July 6, 1975: Comoros | B11: =FIND(":",A11)+LEN(": ") -> 15 | C11: =MID(A11,B11,LEN(A11)) -> Comoros
A12: July 12, 1975: Sao Tome and Principe | B12: =FIND(":",A12)+LEN(": ") -> 16 | C12: =MID(A12,B12,LEN(A12)) -> Sao Tome and Principe
A13: September 16, 1975: Papua New Guinea | B13: =FIND(":",A13)+LEN(": ") -> 21 | C13: =MID(A13,B13,LEN(A13)) -> Papua New Guinea
A14: November 11, 1975: Angola | B14: =FIND(":",A14)+LEN(": ") -> 20 | C14: =MID(A14,B14,LEN(A14)) -> Angola
A15: November 25, 1975: Suriname | B15: =FIND(":",A15)+LEN(": ") -> 20 | C15: =MID(A15,B15,LEN(A15)) -> Suriname
A16: June 29, 1976: Seychelles | B16: =FIND(":",A16)+LEN(": ") -> 16 | C16: =MID(A16,B16,LEN(A16)) -> Seychelles
A17: June 27, 1977: Djibouti | B17: =FIND(":",A17)+LEN(": ") -> 16 | C17: =MID(A17,B17,LEN(A17)) -> Djibouti
A18: July 7, 1978: The Solomon Islands | B18: =FIND(":",A18)+LEN(": ") -> 15 | C18: =MID(A18,B18,LEN(A18)) -> The Solomon Islands
A19: October 1, 1978: Tuvalu | B19: =FIND(":",A19)+LEN(": ") -> 18 | C19: =MID(A19,B19,LEN(A19)) -> Tuvalu
A20: November 3, 1978: Dominica | B20: =FIND(":",A20)+LEN(": ") -> 19 | C20: =MID(A20,B20,LEN(A20)) -> Dominica
... A60: July 9, 2011: South Sudan | B60: =FIND(":",A60)+LEN(": ") -> 15 | C60: =MID(A60,B60,LEN(A60)) -> South Sudan

Sheet Data for 2nd chart
A1: Country | B1: 1975 | C1: 1976 | D1: 1977 | E1: 1978 | F1: 1979 | G1: 1980 | H1: 1981 | I1: 1982 | J1: 1983 | K1: 1984 | L1: 1985 | M1: 1986 | N1: 1987 | O1: 1988 | P1: 1989 | Q1: 1990 | R1: 1991 | S1: 1992 | T1: 1993 | U1: 1994 | V1: 1995 | W1: 1996 | X1: 1997 | Y1: 1998 | Z1: 1999 | AA1: 2000 | AB1: 2001 | AC1: 2002 | AD1: 2003 | AE1: 2004 | AF1: 2005 | AG1: 2006 | AH1: 2007 | AI1: 2008 | AJ1: 2009 | AK1: 2010 | AL1: 2011 | AM1: 2012 | AN1: 2013 | AO1: 2014 | AP1: 2015 | AQ1: 2016 | AR1: 2017 | AS1: 2018 | AT1: 2019 | AU1: 2020 | AV1: 2021 | AW1: 2022 | AX1: 2023 | AY1: 2024 | AZ1: 2025
A2: Afghanistan | AC2: 4367 | AD2: 4553 | AE2: 5146 | AF2: 6167 | AG2: 6925 | AH2: 8556 | AI2: 10297 | AJ2: 12066 | AK2: 15325 | AL2: 17890 | AM2: 20293 | AN2: 20170 | AO2: 20616 | AP2: 20057 | AQ2: 18020 | AR2: 18883 | AS2: 18336 | AT2: 18876 | AU2: 20136 | AV2: 14278 | AW2: 14501 | AX2: 17248
A3: Grenada | E3: 64 | F3: 75 | G3: 111 | H3: 116 | I3: 125 | J3: 132 | K3: 146 | L3: 168 | M3: 188 | N3: 215 | O3: 236
A4: Haiti | P4: 1340 | Q4: 1706 | R4: 1530 | S4: 918 | T4: 1107 | U4: 3054 | V4: 4846 | W4: 5000 | X4: 5748 | Y4: 6408 | Z4: 7148
A5: Iraq | AA5: 25984 | AB5: 21113 | AC5: 21063 | AD5: 15800 | AE5: 36642 | AF5: 50065 | AG5: 65144 | AH5: 88833 | AI5: 131614 | AJ5: 111660 | AK5: 138517 | AL5: 185750 | AM5: 218032 | AN5: 234638 | AO5: 234651 | AP5: 177634 | AQ5: 168429 | AR5: 190048 | AS5: 230189 | AT5: 236682 | AU5: 182576 | AV5: 210753 | AW5: 288059 | AX5: 270799 | AY5: 277478 | AZ5: 258020
A6: Libya | AG6: 60094 | AH6: 68211 | AI6: 86804 | AJ6: 60767 | AK6: 75381 | AL6: 48170 | AM6: 92542 | AN6: 75355 | AO6: 57384 | AP6: 48718 | AQ6: 49913 | AR6: 67153 | AS6: 76682 | AT6: 69237 | AU6: 46893 | AV6: 35216 | AW6: 43281 | AX6: 43958 | AY6: 42159
A7: Niger | AI7: 7279 | AJ7: 7324 | AK7: 7838 | AL7: 8754 | AM7: 9412 | AN7: 10206 | AO7: 10830 | AP7: 9684 | AQ7: 10350 | AR7: 11181 | AS7: 12814 | AT7: 12917 | AU7: 13764 | AV7: 14923 | AW7: 15458 | AX7: 16809 | AY7: 19866 | AZ7: 21874
A8: Pakistan | Z8: 96008 | AA8: 99421 | AB8: 96784 | AC8: 98169 | AD8: 112507 | AE8: 132206 | AF8: 145209 | AG8: 161871 | AH8: 184141 | AI8: 202204 | AJ8: 187074 | AK8: 196712 | AL8: 230577 | AM8: 250094 | AN8: 258674 | AO8: 271422 | AP8: 299930 | AQ8: 313623 | AR8: 339229 | AS8: 356163 | AT8: 321071 | AU8: 300410 | AV8: 348481 | AW8: 374850 | AX8: 337754
A9: Panama | K9: 5700 | L9: 6030 | M9: 6266 | N9: 6294 | O9: 5441 | P9: 5456 | Q9: 5931 | R9: 6522 | S9: 7414 | T9: 8096 | U9: 8633
A10: Philippines | X10: 94106 | Y10: 74492 | Z10: 85640 | AA10: 83667 | AB10: 78921 | AC10: 84307 | AD10: 87039 | AE10: 95002 | AF10: 107420 | AG10: 127653 | AH10: 155980 | AI10: 181007 | AJ10: 176132 | AK10: 208369 | AL10: 234217 | AM10: 261920 | AN10: 283903 | AO10: 297484 | AP10: 306446 | AQ10: 318627 | AR10: 328481 | AS10: 346842 | AT10: 376823 | AU10: 361751 | AV10: 394087 | AW10: 404353
A11: Somalia | AL11: 5022 | AM11: 5183 | AN11: 5869 | AO11: 6443 | AP11: 6841 | AQ11: 7391 | AR11: 8252 | AS11: 7873 | AT11: 8655 | AU11: 8628 | AV11: 9484 | AW11: 10203 | AX11: 10969 | AY11: 12134 | AZ11: 12994
A12: Syria | AJ12: 53939 | AK12: 60043 | AU12: 60043
A13: Uganda | AG13: 14079 | AH13: 17512 | AI13: 22419 | AJ13: 24107 | AK13: 24683 | AL13: 27501 | AM13: 30939 | AN13: 32331 | AO13: 34754 | AP13: 30122 | AQ13: 30232 | AR13: 31589 | AS13: 34126 | AT13: 37895 | AU13: 37889 | AV13: 42805 | AW13: 47276
A14: Yemen | X14: 6838 | Y14: 6322 | Z14: 7639 | AA14: 9679 | AB14: 9853 | AC14: 10693 | AD14: 11778 | AE14: 13868 | AF14: 16732 | AG14: 19063 | AH14: 21651 | AI14: 26911 | AJ14: 25130 | AK14: 30907 | AL14: 32726 | AM14: 35401 | AN14: 40415 | AO14: 43229 | AP14: 42444 | AQ14: 31318 | AR14: 26842 | AS14: 21606 | AT14: 21888 | AU14: 20220 | AV14: 19394 | AW14: 23534 | AX14: 19412 | AY14: 19101 | AZ14: 17401

Sheet Rough for 2nd chart
A1: LEFT and FIND | B1: Country
A2: Grenada (1983 invasion).​ | B2: =LEFT(A2,FIND(" ",A2)) -> Grenada | E2: Year | F2: 1975 | G2: 1976 | H2: 1977 | I2: 1978 | J2: 1979 | K2: 1980 | L2: 1981 | M2: 1982 | N2: 1983 | O2: 1984 | P2: 1985 | Q2: 1986 | R2: 1987 | S2: 1988 | T2: 1989 | U2: 1990 | V2: 1991 | W2: 1992 | X2: 1993 | Y2: 1994 | Z2: 1995 | AA2: 1996 | AB2: 1997 | AC2: 1998 | AD2: 1999 | AE2: 2000 | AF2: 2001 | AG2: 2002 | AH2: 2003 | AI2: 2004 | AJ2: 2005 | AK2: 2006 | AL2: 2007 | AM2: 2008 | AN2: 2009 | AO2: 2010 | AP2: 2011 | AQ2: 2012 | AR2: 2013 | AS2: 2014 | AT2: 2015 | AU2: 2016 | AV2: 2017 | AW2: 2018 | AX2: 2019 | AY2: 2020 | AZ2: 2021 | BA2: 2022 | BB2: 2023 | BC2: 2024 | BD2: 2025
A3: Panama (1989 invasion).​ | B3: =LEFT(A3,FIND(" ",A3)) -> Panama | E3: =GDP_Dashboard!$R$7 -> Afghanistan | F3: =SUMIF('Data for 2nd chart'!$A$2:$A$14,GDP_Dashboard!$R$7,'Data for 2nd chart'!A2:AZ2) -> 0 | G3: =SUMIF('Data for 2nd chart'!$A$2:$A$14,GDP_Dashboard!$R$7,'Data for 2nd chart'!B2:BA2) -> 0 | H3: =SUMIF('Data for 2nd chart'!$A$2:$A$14,GDP_Dashboard!$R$7,'Data for 2nd chart'!C2:BB2) -> 0 | I3: =SUMIF('Data for 2nd chart'!$A$2:$A$14,GDP_Dashboard!$R$7,'Data for 2nd chart'!D2:BC2) -> 0 | J3: =SUMIF('Data for 2nd chart'!$A$2:$A$14,GDP_Dashboard!$R$7,'Data for 2nd chart'!E2:BD2) -> 0 | K3: =SUMIF('Data for 2nd chart'!$A$2:$A$14,GDP_Dashboard!$R$7,'Data for 2nd chart'!F2:BE2) -> 0 | L3: =SUMIF('Data for 2nd chart'!$A$2:$A$14,GDP_Dashboard!$R$7,'Data for 2nd chart'!G2:BF2) -> 0 | M3: =SUMIF('Data for 2nd chart'!$A$2:$A$14,GDP_Dashboard!$R$7,'Data for 2nd chart'!H2:BG2) -> 0 | ... BD3: =SUMIF('Data for 2nd chart'!$A$2:$A$14,GDP_Dashboard!$R$7,'Data for 2nd chart'!AY2:CX2) -> 0
A4: Iraq (1991 Gulf War, Operation Desert Storm).​ | B4: =LEFT(A4,FIND(" ",A4)) -> Iraq | E4: United States | F4: 1623400 | G4: 1809100 | H4: 2013600 | I4: 2276000 | J4: 2543500 | K4: 2857325 | L4: 3207025 | M4: 3343800 | N4: 3634025 | O4: 4037650 | P4: 4339000 | Q4: 4579625 | R4: 4855250 | S4: 5236425 | T4: 5641600 | U4: 5963125 | V4: 6158125 | W4: 6520325 | X4: 6858550 | Y4: 7287250 | Z4: 7639750 | AA4: 8073125 | AB4: 8577550 | AC4: 9062825 | AD4: 9631175 | AE4: 10250950 | AF4: 10581925 | AG4: 10929100 | AH4: 11456450 | AI4: 12217175 | AJ4: 13039200 | AK4: 13815600 | AL4: 14474250 | AM4: 14769850 | AN4: 14478050 | AO4: 15048975 | AP4: 15599725 | AQ4: 16253950 | AR4: 16880675 | AS4: 17608125 | AT4: 18295000 | AU4: 18804900 | AV4: 19612100 | AW4: 20656525 | AX4: 21539975 | AY4: 21354125 | AZ4: 23681175 | BA4: 26006900 | BB4: 27720725 | BC4: 29184900 | BD4: 30507217
A5: Somalia (1992–1993, Operation Restore Hope, 2007–present vs. al-Shabaab).​ | B5: =LEFT(A5,FIND(" ",A5)) -> Somalia
A6: Haiti (1994 intervention).​ | B6: =LEFT(A6,FIND(" ",A6)) -> Haiti | E6: Year | F6: 1975 | G6: 1976 | H6: 1977 | I6: 1978 | J6: 1979 | K6: 1980 | L6: 1981 | M6: 1982 | N6: 1983 | O6: 1984 | P6: 1985 | Q6: 1986 | R6: 1987 | S6: 1988 | T6: 1989 | U6: 1990 | V6: 1991 | W6: 1992 | X6: 1993 | Y6: 1994 | Z6: 1995 | AA6: 1996 | AB6: 1997 | AC6: 1998 | AD6: 1999 | AE6: 2000 | AF6: 2001 | AG6: 2002 | AH6: 2003 | AI6: 2004 | AJ6: 2005 | AK6: 2006 | AL6: 2007 | AM6: 2008 | AN6: 2009 | AO6: 2010 | AP6: 2011 | AQ6: 2012 | AR6: 2013 | AS6: 2014 | AT6: 2015 | AU6: 2016 | AV6: 2017 | AW6: 2018 | AX6: 2019 | AY6: 2020 | AZ6: 2021 | BA6: 2022 | BB6: 2023 | BC6: 2024 | BD6: 2025
